<?xml version="1.0" ?>
<!-- Author: Tri Knight-->
<!-- Email: nvn.bienminhtri@gmail.com-->
<!-- =================================================================================== -->
<!-- |    This document was autogenerated by xacro from ur10_robot.urdf.xacro          | -->
<!-- |    EDITING THIS FILE BY HAND IS NOT RECOMMENDED                                 | -->
<!-- =================================================================================== -->
<robot name="ur10" xmlns:xacro="http://www.ros.org/wiki/xacro">
  <!-- ur10 -->
  <!-- arm -->
  <link name="base_link">
    <visual>
      <geometry>
        <mesh filename="package://meshes/visual/Base.dae"/>
      </geometry>
      
    </visual>
    <collision>
      <geometry>
        <mesh filename="package://meshes/collision/base.stl"/>
      </geometry>
    </collision>
    <inertial>
      <mass value="4.0"/>
      <origin rpy="0 0 0" xyz="0.0 0.0 0.0"/>
      <inertia ixx="0.0061063308908" ixy="0.0" ixz="0.0" iyy="0.0061063308908" iyz="0.0" izz="0.01125"/>
    </inertial>
  </link>
  <joint name="shoulder_pan_joint" type="revolute">
    <parent link="base_link"/>
    <child link="shoulder_link"/>
    <origin rpy="0.0 0.0 0.0" xyz="0.0 0.0 0.1273"/>
    <axis xyz="0 0 1"/>
    <limit effort="330.0" lower="-6.2831853" upper="6.2831853" velocity="2.16"/>
    <dynamics damping="0.0" friction="0.0"/>
  </joint>
  <link name="shoulder_link">
    <visual>
      <geometry>
        <mesh filename="package://meshes/visual/Shoulder.dae"/>
      </geometry>
     
    </visual>
    <collision>
      <geometry>
        <mesh filename="package://meshes/collision/shoulder.stl"/>
      </geometry>
    </collision>
    <inertial>
      <mass value="7.778"/>
      <origin rpy="0 0 0" xyz="0.0 0.0 0.0"/>
      <inertia ixx="0.0314743125769" ixy="0.0" ixz="0.0" iyy="0.0314743125769" iyz="0.0" izz="0.021875625"/>
    </inertial>
  </link>
  <joint name="shoulder_lift_joint" type="revolute">
    <parent link="shoulder_link"/>
    <child link="upper_arm_link"/>
    <origin rpy="0.0 1.570796325 0.0" xyz="0.0 0.220941 0.0"/>
    <axis xyz="0 1 0"/>
    <limit effort="330.0" lower="-6.2831853" upper="6.2831853" velocity="2.16"/>
    <dynamics damping="0.0" friction="0.0"/>
  </joint>
  <link name="upper_arm_link">
    <visual>
      <geometry>
        <mesh filename="package://meshes/visual/UpperArm.dae"/>
      </geometry>
   
    </visual>
    <collision>
      <geometry>
        <mesh filename="package://meshes/collision/upper_arm.stl"/>
      </geometry>
    </collision>
    <inertial>
      <mass value="12.93"/>
      <origin rpy="0 0 0" xyz="0.0 0.0 0.306"/>
      <inertia ixx="0.421753803798" ixy="0.0" ixz="0.0" iyy="0.421753803798" iyz="0.0" izz="0.036365625"/>
    </inertial>
  </link>
  <joint name="elbow_joint" type="revolute">
    <parent link="upper_arm_link"/>
    <child link="forearm_link"/>
    <origin rpy="0.0 0.0 0.0" xyz="0.0 -0.1719 0.612"/>
    <axis xyz="0 1 0"/>
    <limit effort="150.0" lower="-6.2831853" upper="6.2831853" velocity="3.15"/>
    <dynamics damping="0.0" friction="0.0"/>
  </joint>
  <link name="forearm_link">
    <visual>
      <geometry>
        <mesh filename="package://meshes/visual/Forearm.dae"/>
      </geometry>

    </visual>
    <collision>
      <geometry>
        <mesh filename="package://meshes/collision/forearm.stl"/>
      </geometry>
    </collision>
    <inertial>
      <mass value="3.87"/>
      <origin rpy="0 0 0" xyz="0.0 0.0 0.28615"/>
      <inertia ixx="0.111069694097" ixy="0.0" ixz="0.0" iyy="0.111069694097" iyz="0.0" izz="0.010884375"/>
    </inertial>
  </link>
  <joint name="wrist_1_joint" type="revolute">
    <parent link="forearm_link"/>
    <child link="wrist_1_link"/>
    <origin rpy="0.0 1.570796325 0.0" xyz="0.0 0.0 0.5723"/>
    <axis xyz="0 1 0"/>
    <limit effort="54.0" lower="-6.2831853" upper="6.2831853" velocity="3.2"/>
    <dynamics damping="0.0" friction="0.0"/>
  </joint>
  <link name="wrist_1_link">
    <visual>
      <geometry>
        <mesh filename="package://meshes/visual/Wrist1.dae"/>
      </geometry>

    </visual>
    <collision>
      <geometry>
        <mesh filename="package://meshes/collision/wrist_1.stl"/>
      </geometry>
    </collision>
    <inertial>
      <mass value="1.96"/>
      <origin rpy="0 0 0" xyz="0.0 0.0 0.0"/>
      <inertia ixx="0.0051082479567" ixy="0.0" ixz="0.0" iyy="0.0051082479567" iyz="0.0" izz="0.0055125"/>
    </inertial>
  </link>
  <joint name="wrist_2_joint" type="revolute">
    <parent link="wrist_1_link"/>
    <child link="wrist_2_link"/>
    <origin rpy="0.0 0.0 0.0" xyz="0.0 0.1149 0.0"/>
    <axis xyz="0 0 1"/>
    <limit effort="54.0" lower="-6.2831853" upper="6.2831853" velocity="3.2"/>
    <dynamics damping="0.0" friction="0.0"/>
  </joint>
  <link name="wrist_2_link">
    <visual>
      <geometry>
        <mesh filename="package://meshes/visual/Wrist2.dae"/>
      </geometry>

    </visual>
    <collision>
      <geometry>
        <mesh filename="package://meshes/collision/wrist_2.stl"/>
      </geometry>
    </collision>
    <inertial>
      <mass value="1.96"/>
      <origin rpy="0 0 0" xyz="0.0 0.0 0.0"/>
      <inertia ixx="0.0051082479567" ixy="0.0" ixz="0.0" iyy="0.0051082479567" iyz="0.0" izz="0.0055125"/>
    </inertial>
  </link>
  <joint name="wrist_3_joint" type="revolute">
    <parent link="wrist_2_link"/>
    <child link="wrist_3_link"/>
    <origin rpy="0.0 0.0 0.0" xyz="0.0 0.0 0.1157"/>
    <axis xyz="0 1 0"/>
    <limit effort="54.0" lower="-6.2831853" upper="6.2831853" velocity="3.2"/>
    <dynamics damping="0.0" friction="0.0"/>
  </joint>
  <link name="wrist_3_link">
    <visual>
      <geometry>
        <mesh filename="package://meshes/visual/Wrist3.dae"/>
      </geometry>
    </visual>
    <collision>
      <geometry>
        <mesh filename="package://meshes/collision/wrist_3.stl"/>
      </geometry>
    </collision>
    <inertial>
      <mass value="0.202"/>
      <origin rpy="0 0 0" xyz="0.0 0.0 0.0"/>
      <inertia ixx="0.000526462289415" ixy="0.0" ixz="0.0" iyy="0.000526462289415" iyz="0.0" izz="0.000568125"/>
    </inertial>
  </link>
  <link name="world"/>
  <joint name="world_joint" type="fixed">
    <parent link="world"/>
    <child link="base_link"/>
    <origin rpy="0.0 0.0 0.0" xyz="0.0 0.0 0.0"/>
  </joint> 

  <!-- Adding end effector-->
   <!-- Arm-Hand Fixed Joint -->
  <joint name="ur10_hand_joint" type="fixed">
    <parent link="wrist_3_link"/>
    <child link="rg2_hand"/>
    <origin xyz="0 0.0823 0" rpy="1.570796325 0 1.570796325"/>
    <limit lower="0" upper="0" effort="0" velocity="0"/>
  </joint>


  <!-- Hand Links -->
  <link name="rg2_hand">
    <visual name="rg2_hand_visual">
      <geometry>
        <mesh filename="package://meshes/visual/rg2/hand.dae"/>
      </geometry>
    </visual>
    <collision name="rg2_hand_collision">
      <geometry>
        <mesh filename="package://meshes/collision/rg2/hand.stl"/>
      </geometry>
    </collision>
    <inertial>
      <mass value="0.29881464108881906"/>
      <origin rpy="0.057581 -0.000169308 -3.3334e-05" xyz="0.0 0.0 0.0"/>
      <inertia ixx="0.00010934311942148434" ixy="2.4297126288189813e-07" ixz="5.3958894994201004e-08" iyy="0.0003327568173229071" iyz="2.4899876853227836e-07" izz="0.00037338963627732164"/>
    </inertial>
  </link>

  <link name="rg2_leftfinger">
    <visual>
      <geometry>
        <mesh filename="package://meshes/visual/rg2/finger.dae" />
      </geometry>
    </visual>
    <collision>
      <geometry>
        <mesh filename="package://meshes/collision/rg2/finger.stl" />
      </geometry>
    </collision>
    <inertial>
      <mass value="0.202"/>
      <origin rpy="0 0 0" xyz="0.0 0.0 0.0"/>
      <inertia ixx="0.000526462289415" ixy="0.0" ixz="0.0" iyy="0.000526462289415" iyz="0.0" izz="0.000568125"/>
    </inertial>
  </link>

  <link name="rg2_rightfinger">
    <visual>
      <origin rpy="3.141592653589793 0 0" xyz="0 0 0" />
      <geometry>
        <mesh filename="package://meshes/visual/rg2/finger.dae" />
      </geometry>
    </visual>
    <collision>
      <origin rpy="3.141592653589793 0 0" xyz="0 0 0" />
      <geometry>
        <mesh filename="package://meshes/collision/rg2/finger.stl" />
      </geometry>
    </collision>
    <inertial>
      <mass value="0.202"/>
      <origin rpy="0 0 0" xyz="0.0 0.0 0.0"/>
      <inertia ixx="0.000526462289415" ixy="0.0" ixz="0.0" iyy="0.000526462289415" iyz="0.0" izz="0.000568125"/>
    </inertial>
  </link>


  <!-- Finger Joints -->
  <joint name="rg2_finger_joint1" type="revolute">
    <parent link="rg2_hand"/>
    <child link="rg2_leftfinger"/>
    <origin rpy="0 0 0" xyz="0.105 0.017 0"/>
    <axis xyz="0 0 1" />
    <limit effort="10.6" lower="0.0" upper="1.18" velocity="1.57" />
  </joint>

  <joint name="rg2_finger_joint2" type="revolute">
    <parent link="rg2_hand" />
    <child link="rg2_rightfinger" />
    <origin rpy="0 0 0" xyz="0.105 -0.017 0"/>
    <axis xyz="0 0 -1" />
    <limit effort="10.6" lower="0.0" upper="1.18" velocity="1.57" />
    <mimic joint="panda_finger_joint1" />
  </joint>


  <!-- End-effector -->
  <link name="tool0">
  <inertial>
      <mass value="0.0"/>
      <origin rpy="0 0 0" xyz="0.0 0.0 0.0"/>
      <inertia ixx="1" ixy="0.0" ixz="0.0" iyy="1" iyz="0.0" izz="1"/>
    </inertial>
  </link>
  <joint name="end_effector_frame_fixed_joint" type="fixed">
    <parent link="wrist_3_link"/>
    <child link="tool0"/>
    <origin xyz="0 0.275 0" rpy="-1.570796325 0 0"/>
  </joint>

</robot>

